Workbook

Sheet lista
A1: Codigo | B1: Descripcion | C1: P. nuevo
B2: BLANCO SEIN 40 X 50 | C2: 27511 | E2: 0 | F2: =ROUND(C2,0) -> 27511 | H2: =_xlfn.XLOOKUP(A2,Hoja1!A:A,Hoja1!G:G,0,0) -> #NAME?
A3: 0001BCO00003 | B3: BLANCO SEIN 64 X 90 | C3: 27511 | E3: 0 | F3: =ROUND(C3,0) -> 27511 | H3: =_xlfn.XLOOKUP(A3,Hoja1!A:A,Hoja1!G:G,0,0) -> #NAME?
A4: 0001BCO00004 | B4: BLANCO SEIN 64 X 45 | C4: 27511 | E4: 0 | F4: =ROUND(C4,0) -> 27511 | H4: =_xlfn.XLOOKUP(A4,Hoja1!A:A,Hoja1!G:G,0,0) -> #NAME?
A5: 0001BCO00005 | B5: BLANCO SEIN 32 X 45 | C5: 27511 | E5: 0 | F5: =ROUND(C5,0) -> 27511 | H5: =_xlfn.XLOOKUP(A5,Hoja1!A:A,Hoja1!G:G,0,0) -> #NAME?
A6: 0001BCO00006 | B6: BLANCO SEIN 52 X 72 | C6: 27511 | E6: 0 | F6: =ROUND(C6,0) -> 27511 | H6: =_xlfn.XLOOKUP(A6,Hoja1!A:A,Hoja1!G:G,0,0) -> #NAME?
A7: 0001BCO00007 | B7: BLANCO SEIN 52 X 36 | C7: 27511 | E7: 0 | F7: =ROUND(C7,0) -> 27511 | H7: =_xlfn.XLOOKUP(A7,Hoja1!A:A,Hoja1!G:G,0,0) -> #NAME?
A8: 0001BCO00008 | B8: BLANCO SEIN 26 X 36 | C8: 27511 | E8: 0 | F8: =ROUND(C8,0) -> 27511 | H8: =_xlfn.XLOOKUP(A8,Hoja1!A:A,Hoja1!G:G,0,0) -> #NAME?
A9: 0001BCO00009 | B9: BLANCO SEIN 26 X 18 | C9: 27511 | E9: 0 | F9: =ROUND(C9,0) -> 27511 | H9: =_xlfn.XLOOKUP(A9,Hoja1!A:A,Hoja1!G:G,0,0) -> #NAME?
A10: 0001BCO00010 | B10: BLANCO SEIN 58 X 81 | C10: 27511 | E10: 0 | F10: =ROUND(C10,0) -> 27511 | H10: =_xlfn.XLOOKUP(A10,Hoja1!A:A,Hoja1!G:G,0,0) -> #NAME?
A11: 0001BCO00011 | B11: BLANCO SEIN 58 X 40 | C11: 27511 | E11: 0 | F11: =ROUND(C11,0) -> 27511 | H11: =_xlfn.XLOOKUP(A11,Hoja1!A:A,Hoja1!G:G,0,0) -> #NAME?
A12: 0001BCO00014 | B12: BLANCO SEIN 9 X 13 PIZZERO | C12: 27511 | E12: 0 | F12: =ROUND(C12,0) -> 27511 | H12: =_xlfn.XLOOKUP(A12,Hoja1!A:A,Hoja1!G:G,0,0) -> #NAME?
A13: 0001BCO00015 | B13: BLANCO SEIN 30 X 40 | C13: 27511 | E13: 0 | F13: =ROUND(C13,0) -> 27511 | H13: =_xlfn.XLOOKUP(A13,Hoja1!A:A,Hoja1!G:G,0,0) -> #NAME?
A14: 0001BCP00002 | B14: SULFITO PRIMERA 40 X 50 | C14: 36341 | E14: 0 | F14: =ROUND(C14,0) -> 36341 | H14: =_xlfn.XLOOKUP(A14,Hoja1!A:A,Hoja1!G:G,0,0) -> #NAME?
... A81: 0012COM00006 | B81: BANDEJA DE CARTON Nº 6 21X29 | C81: 12216 | E81: 0.15 | F81: =ROUND(C81,0) -> 12216 | H81: =_xlfn.XLOOKUP(A81,Hoja1!A:A,Hoja1!G:G,0,0) -> #NAME?
A82: 0012COM00051 | B82: BANDEJA KRAFT PURO N°1 (6PX100U) | C82: 15561 | F82: =ROUND(C82,0) -> 15561 | H82: =_xlfn.XLOOKUP(A82,Hoja1!A:A,Hoja1!G:G,0,0) -> #NAME?
A83: 0012COM00052 | B83: BANDEJA KRAFT PURO N°2 (6PX100U) | C83: 37544 | E83: 0.07 | F83: =ROUND(C83,0) -> 37544 | H83: =_xlfn.XLOOKUP(A83,Hoja1!A:A,Hoja1!G:G,0,0) -> #NAME?
A84: 0012COM00053 | B84: BANDEJA KRAFT PURO N°3 (4PX100U) | C84: 32214 | F84: =ROUND(C84,0) -> 32214 | H84: =_xlfn.XLOOKUP(A84,Hoja1!A:A,Hoja1!G:G,0,0) -> #NAME?
A85: 0012COM00054 | B85: BANDEJA KRAFT PURO N°4 (2PX100U) | C85: 20915 | F85: =ROUND(C85,0) -> 20915 | H85: =_xlfn.XLOOKUP(A85,Hoja1!A:A,Hoja1!G:G,0,0) -> #NAME?
A86: 0012COM10002 | B86: BANDEJA MICRO CORRUGADO N° 2 (4PX100U) | C86: 22142 | E86: 0.07 | F86: =ROUND(C86,0) -> 22142 | H86: =_xlfn.XLOOKUP(A86,Hoja1!A:A,Hoja1!G:G,0,0) -> #NAME?
A87: 0012COM10003 | B87: BANDEJA MICRO CORRUGADO N° 3 (4PX100U) | C87: 25437 | E87: 0.07 | F87: =ROUND(C87,0) -> 25437 | H87: =_xlfn.XLOOKUP(A87,Hoja1!A:A,Hoja1!G:G,0,0) -> #NAME?
A88: 0012COM10004 | B88: BANDEJA MICRO CORRUGADO N° 4 (4PX100U) | C88: 33184 | E88: 0 | F88: =ROUND(C88,0) -> 33184 | H88: =_xlfn.XLOOKUP(A88,Hoja1!A:A,Hoja1!G:G,0,0) -> #NAME?
A89: 0012COM10005 | B89: BANDEJA MICRO CORRUGADO N° 5 (2PX100U) | C89: 21092 | E89: 0.03 | F89: =ROUND(C89,0) -> 21092 | H89: =_xlfn.XLOOKUP(A89,Hoja1!A:A,Hoja1!G:G,0,0) -> #NAME?
A90: 0012COM10006 | B90: BANDEJA MICRO CORRUGADO N° 6 (4P X 50U) | C90: 18340 | E90: 0.02 | F90: =ROUND(C90,0) -> 18340 | H90: =_xlfn.XLOOKUP(A90,Hoja1!A:A,Hoja1!G:G,0,0) -> #NAME?
A91: 0012COM10012 | B91: BANDEJA MICRO CORRUGADO N°2 IMPRESA | C91: 37414 | E91: 0.03 | F91: =ROUND(C91,0) -> 37414 | H91: =_xlfn.XLOOKUP(A91,Hoja1!A:A,Hoja1!G:G,0,0) -> #NAME?
A92: 0012COM10013 | B92: BANDEJA MICRO CORRUGADO N°3 IMPRESA | C92: 43394 | E92: 0.02 | F92: =ROUND(C92,0) -> 43394 | H92: =_xlfn.XLOOKUP(A92,Hoja1!A:A,Hoja1!G:G,0,0) -> #NAME?
A93: 0012COM10014 | B93: BANDEJA MICRO CORRUGADO N°4 IMPRESA | C93: 54601 | E93: 0.02 | F93: =ROUND(C93,0) -> 54601 | H93: =_xlfn.XLOOKUP(A93,Hoja1!A:A,Hoja1!G:G,0,0) -> #NAME?
A94: 0012COM10015 | B94: BANDEJA MICRO CORRUGADO N°5 IMPRESA | C94: 33720 | E94: 0.02 | F94: =ROUND(C94,0) -> 33720 | H94: =_xlfn.XLOOKUP(A94,Hoja1!A:A,Hoja1!G:G,0,0) -> #NAME?
A95: 0012COM10016 | B95: BANDEJA MICRO CORRUGADO N°6 IMPRESA | C95: 28301 | E95: 0.02 | F95: =ROUND(C95,0) -> 28301 | H95: =_xlfn.XLOOKUP(A95,Hoja1!A:A,Hoja1!G:G,0,0) -> #NAME?
A96: 0012COM10017 | B96: BANDEJA MICRO CORRUGADO N°7 IMPRESA | C96: 34372 | E96: 0.02 | F96: =ROUND(C96,0) -> 34372 | H96: =_xlfn.XLOOKUP(A96,Hoja1!A:A,Hoja1!G:G,0,0) -> #NAME?
A97: 0013COM00016 | B97: DISCO DE CARTON 16 CM (X 5KG) | C97: 24235 | E97: 0.02 | F97: =ROUND(C97,0) -> 24235 | H97: =_xlfn.XLOOKUP(A97,Hoja1!A:A,Hoja1!G:G,0,0) -> #NAME?
... A124: 0018DARBK0066 | B124: CAJA PARA ALIMENTOS DARNEL NATURAL 66 Oz MOCA PQX50 CJX200 | C124: 74222 | E124: 0 | F124: =ROUND(C124,0) -> 74222 | H124: =_xlfn.XLOOKUP(A124,Hoja1!A:A,Hoja1!G:G,0,0) -> #NAME?
A125: 0018DARBKF0001 | B125: CAJA PEQUEÑA PARA PAPAS FRITAS DARNEL NATURAL MOCA PQX100 CJX600 | C125: 29445 | F125: =ROUND(C125,0) -> 29445 | H125: =_xlfn.XLOOKUP(A125,Hoja1!A:A,Hoja1!G:G,0,0) -> #NAME?
A126: 0018DARBKS0049 | B126: CAJA PARA ALIMENTOS SAFETYPLUS DARNEL NATURAL 49 Oz MOCA PQX50CJX200 | C126: 72723 | E126: 0 | F126: =ROUND(C126,0) -> 72723 | H126: =_xlfn.XLOOKUP(A126,Hoja1!A:A,Hoja1!G:G,0,0) -> #NAME?
A127: 0018DARBKS0066 | B127: CAJA PARA ALIMENTOS SAFETYPLUS DARNEL NAT 66oz MOCA PQX50 CJX200 | C127: 79883 | E127: 0 | F127: =ROUND(C127,0) -> 79883 | H127: =_xlfn.XLOOKUP(A127,Hoja1!A:A,Hoja1!G:G,0,0) -> #NAME?
A128: 0018DARBKS026 | B128: CAJA PARA ALIMENTOS SAFETYPLUS DARNEL NATURAL 26 Oz MOCA PQX50 CAJX200 | C128: 45268 | E128: 0 | F128: =ROUND(C128,0) -> 45268 | H128: =_xlfn.XLOOKUP(A128,Hoja1!A:A,Hoja1!G:G,0,0) -> #NAME?
A129: 0018DARBKS045 | B129: CAJA ALIMENTOS SAFETYPLUS DARNEL NATURALS 45 Oz MOCA PQX50 CAJX200 | C129: 67623 | E129: 0 | F129: =ROUND(C129,0) -> 67623 | H129: =_xlfn.XLOOKUP(A129,Hoja1!A:A,Hoja1!G:G,0,0) -> #NAME?
A130: 0018DARKH0001 | B130: CAJA PEQUEÑA PARA HAMBURGUESA DARNEL NATURAL MOCA PAQX50 CAJ X300UNI | C130: 44059 | E130: 0 | F130: =ROUND(C130,0) -> 44059 | H130: =_xlfn.XLOOKUP(A130,Hoja1!A:A,Hoja1!G:G,0,0) -> #NAME?
A131: 0018DARKH0005 | B131: CAJA MEDIANA PARA HAMBURGUESA DARNEL NATURAL MOCA PAQX50 CAJ X300 UNI | C131: 45245 | E131: 0 | F131: =ROUND(C131,0) -> 45245 | H131: =_xlfn.XLOOKUP(A131,Hoja1!A:A,Hoja1!G:G,0,0) -> #NAME?
A132: 0018DARKH0010 | B132: CAJA GRANDE PARA HAMBURGUESA DARNEL NATURAL MOCA PAQX50 CAJX300 | C132: 55794 | E132: 0 | F132: =ROUND(C132,0) -> 55794 | H132: =_xlfn.XLOOKUP(A132,Hoja1!A:A,Hoja1!G:G,0,0) -> #NAME?
...

Sheet Hoja1
A3: {=_xlfn.VSTACK('Papeles-Cartulina'!B6:H69,PVC!B7:H31,'Porta Comida XPS'!B6:H28,'Band. Expandido'!B7:H47,'Linea Aluminio'!B6:H54)} -> 0001BIO00002 | B3: 0 | C3: kg | D3: 1 | E3: BIOXIDO 75 X 50 | F3: Resma 10 KG. | G3: 72428
A4: 0001BIO00004 | B4: 0 | C4: kg | D4: 1 | E4: BIOXIDO 37 X 50 | F4: Resma 10 KG. | G4: 72428
A5: 0001BIO00008 | B5: 0 | C5: kg | D5: 1 | E5: BIOXIDO 37 X 25 | F5: Resma 10 KG. | G5: 72428
A6: 0001BIO00016 | B6: 0 | C6: kg | D6: 1 | E6: BIOXIDO 18 X 25 | F6: Resma 10 KG. | G6: 72428
A7: 0002DES03246 | B7: 0 | C7: res | D7: 1 | E7: DESMOLDANTE 32 X 46 | F7: Resma 5 KG. | G7: 64589
A8: 0002DES04060 | B8: 0 | C8: res | D8: 1 | E8: DESMOLDANTE 40 X 60 | F8: Resma 5 KG. | G8: 64589
A9: 0002DES04565 | B9: 0 | C9: res | D9: 1 | E9: DESMOLDANTE 45 X 64 | F9: Resma 5 KG. | G9: 64589
A10: 0002DES06080 | B10: 0 | C10: res | D10: 1 | E10: DESMOLDANTE 60 X 80 | F10: Resma 5 KG. | G10: 64589
A11: 0002DES07090 | B11: 0 | C11: res | D11: 1 | E11: DESMOLDANTE 70 X 90 | F11: Resma 5 KG. | G11: 64589
A12: PAPEL PARAFINADO | B12: 0 | C12: 0 | D12: 0 | E12: 0 | F12: 0 | G12: 0
A13: 0082ALL00009 | B13: 0 | C13: res | D13: 1 | E13: PAPEL PARAFINADO LISO 40 x 40 cm | F13: Resma 1 KG. | G13: 12994
A14: 0082ALL00020 | B14: 0 | C14: res | D14: 1 | E14: PAPEL PARAFINADO LISO 35 x 40 cm | F14: Resma 5 KG. | G14: 64439
A15: 0082ALL00021 | B15: 0 | C15: res | D15: 1 | E15: PAPEL PARAFINADO GENERICO 35 x 40 cm | F15: Resma 5 KG. | G15: 64566
A16: 0082ALL00022 | B16: 0 | C16: res | D16: 1 | E16: PAPEL PARAFINADO PERSONALIZADO | F16: Resma 5 KG. | G16: 64276
A17: PAPEL ALUMINIZADO | B17: 0 | C17: 0 | D17: 0 | E17: 0 | F17: 0 | G17: 0
A18: 0082ALL00002 | B18: 0 | C18: res | D18: 1 | E18: PAPEL ALUMINIO IMPRESO GENERICO 25 x 35 cm | F18: Resma 5 KG. | G18: 125496
A19: 0082ALL00003 | B19: 0 | C19: res | D19: 1 | E19: PAPEL ALUMINIO PERSONALIZADO | F19: Resma 5 KG. | G19: 125185
A20: 0082ALL00004 | B20: 0 | C20: res | D20: 1 | E20: PAPEL ALUMINIO LISO 25 x 35 cm | F20: Resma 5 KG. | G20: 126192
A21: 0082ALL00005 | B21: 0 | C21: res | D21: 1 | E21: PAPEL ALUMINIO LISO 34 x 50 cm | F21: Resma 5 KG. | G21: 126192
A22: 0082ALL00006 | B22: 0 | C22: res | D22: 1 | E22: PAPEL ALUMINIO IMPRESO GENERICO 34 x 50 cm | F22: Resma 5 KG. | G22: 125844
A23: CARTON - CARTULINA ANTIGRASA | B23: 0 | C23: 0 | D23: 0 | E23: 0 | F23: 0 | G23: 0
A24: 0018DARBB0026 | B24: RPN02026101XC | C24: caja | D24: 200 | E24: CAJA PARA ALIMENTOS DARNEL NATURAL 26 Oz BLANCA PAQX50 Un. | F24: Nuevo | G24: 47151
A25: 0018DARBK0026 | B25: RPN02026102XC | C25: PAQ | D25: 200 | E25: CAJA PARA ALIMENTOS DARNEL NATURAL 26 Oz MOCA PAQX50 CAJ X200UNID | F25: Nuevo | G25: 43116
A26: 0018DARBB0045 | B26: RPN02045101XC | C26: PAQ | D26: 200 | E26: CAJA PARA ALIMENTOS DARNEL NATURAL 45 Oz BLANCO PQX50 CJX200 | F26: Nuevo | G26: 68591
A27: 0018DARBKS045 | B27: RPN02045102XTE | C27: PAQ | D27: 200 | E27: CAJA ALIMENTOS SAFETYPLUS DARNEL NATURALS 45 Oz MOCA PQX50 CAJX200 | F27: Nuevo | G27: 67623
A28: 0018DARBB0049 | B28: RPN02049101XC | C28: PAQ | D28: 200 | E28: CAJA PARA ALIMENTOS DARNEL NATURALS 49 Oz BLANCO PQX50 CAJX200 | F28: Nuevo | G28: 73442
A29: 0018DARBK0049 | B29: RPN02049102XC | C29: PAQ | D29: 200 | E29: CAJA PARA ALIMENTOS DARNEL NATURAL 49 Oz MOCA PQX50 CJX200 | F29: Nuevo | G29: 67949
A30: 0018DARBB0066 | B30: RPN02066101XC | C30: PAQ | D30: 200 | E30: CAJA PARA ALIMENTOS DARNEL NATURAL 66 Oz BLANCO PQX50 CJX200 | F30: Nuevo | G30: 80488
A31: 0018DARBK0066 | B31: RPN02066102XC | C31: PAQ | D31: 200 | E31: CAJA PARA ALIMENTOS DARNEL NATURAL 66 Oz MOCA PQX50 CJX200 | F31: Nuevo | G31: 74222
A32: 0018DARBB0072 | B32: RPN0207201X | C32: PAQ | D32: 100 | E32: CAJA PARA ALIMENTOS DARNEL NATURALS 72 Oz BLANCO BLX100 | F32: Nuevo | G32: 50051
A33: 0018DARBBK072 | B33: RPN0207202X | C33: PAQ | D33: 100 | E33: CAJA PARA ALIMENTOS DARNEL NATURALS 72 Oz MOCA BLX100 | F33: Nuevo | G33: 50375
A34: 0018DARBB0115 | B34: RPN02011501X | C34: PAQ | D34: 100 | E34: CAJA PARA ALIMENTOS DARNEL NATURALS 115 Oz BLANCO BLX100 UNID | F34: Nuevo | G34: 43095
A35: 0018DARBBK115 | B35: RPN02011502X | C35: caja | D35: 100 | E35: CAJA PARA ALIMENTOS DARNEL NATURAL 115oz MOCA | F35: Nuevo | G35: 43428
A36: CAJAS y ESTUCHES PARA PAPAS FRITAS | B36: 0 | C36: 0 | D36: 0 | E36: 0 | F36: 0 | G36: 0
A37: 0018DARBBF0001 | B37: RPN02P08201X | C37: PAQ | D37: 600 | E37: CAJA PEQUEÑA PARA PAPAS FRITAS DARNEL NATURAL BLANCA PQX100 CJX600 | F37: Nuevo | G37: 33056
A38: 0018DARBBF0005 | B38: RPN02P08701X | C38: PAQ | D38: 600 | E38: CAJA MEDIANA PARA PAPAS FRITAS DARNEL NATURAL BLANCO PQX100 CJX600 | F38: Nuevo | G38: 60322
A39: 0018DARBBF0010 | B39: RPN02P12801X | C39: PAQ | D39: 600 | E39: CAJA GRANDE PARA PAPAS FRITAS DARNEL NATURAL BLANCO PQX100 CJX600 | F39: Nuevo | G39: 81948
A40: 0018DARBKF0001 | B40: RPN02P08202X | C40: PAQ | D40: 600 | E40: CAJA PEQUEÑA PARA PAPAS FRITAS DARNEL NATURAL MOCA PQX100 CJX600 | F40: Nuevo | G40: 29445
A41: 0018ESP00004 | B41: 0018ESP00004 | C41: PAQ | D41: 1000 | E41: ESTUCHES PAPAS FRITAS KRAFT X 1000 | F41: 210 Grs (Aprox) | G41: 97504
A42: CAJAS PARA ALIMENTOS SAFETYPLUS | B42: 0 | C42: 0 | D42: 0 | E42: 0 | F42: 0 | G42: 0
...

Sheet amb
A1: SIS8120-Consulta dinamica
A3: Nombre Articulo | B3: Articulo | C3: Articulo Interno | D3: Articulo Formularios | E3: Cantidad Bulto | F3: Peso embalado | G3: Cantidad Bulto (Vent) | H3: Unidad Medida homogenea (Vent) | I3: Nombre Unidad de Medida | J3: Unidad de Medida_1 | K3: Unidad de medidad Utilizable | L3: Unidad de Medida_2 | M3: Clasificacion 1 | N3: Clasificacion 1 Utilizable | O3: Nombre Clasificacion 1 | P3: Clasificacion 2 | Q3: Nombre Clasificacion 2 | R3: Clasificacion 2 Utilizable | S3: Clasificacion 3 | T3: Nombre Clasificacion 3 | U3: Clasificacion 3 Utilizable | V3: Clasificacion 4 | W3: Nombre Clasificacion 4 | X3: Clasificacion 4 Utilizable | Y3: Formato | Z3: Simbolo | AA3: Clasificacion 5 | AB3: Nombre Clasificacion 5 | AC3: Clasificacion 5 Utilizable | AD3: Fecha de baja (Comp) | AE3: Fecha Baja
A4: BLANCO SEIN 40 X 50 | B4: 0001BCO00002 | C4: 1 | D4: 0001BCO00002 | E4: .0000 | F4: 10.0000 | G4: .0000 | I4: Resmas | K4: 1 | L4: RES | M4: 007 | N4: 1 | O4: Papeles | P4: 001 | Q4: Papel | R4: 1 | S4: 001 | T4: Manufactured Group Locally | U4: 1 | V4: 001 | W4: Bolsas de Papel | X4: 1 | Z4: RES | AA4: 1 | AB4: 1 | AC4: 1
A5: BLANCO SEIN 64 X 90 | B5: 0001BCO00003 | C5: 2 | D5: 0001BCO00003 | E5: .0000 | F5: 10.0000 | G5: .0000 | I5: Resmas | K5: 1 | L5: RES | M5: 007 | N5: 1 | O5: Papeles | P5: 001 | Q5: Papel | R5: 1 | S5: 001 | T5: Manufactured Group Locally | U5: 1 | V5: 001 | W5: Bolsas de Papel | X5: 1 | Z5: RES | AA5: 1 | AB5: 1 | AC5: 1
A6: BLANCO SEIN 64 X 45 | B6: 0001BCO00004 | C6: 3 | D6: 0001BCO00004 | E6: .0000 | F6: 10.0000 | G6: .0000 | I6: Resmas | K6: 1 | L6: RES | M6: 007 | N6: 1 | O6: Papeles | P6: 001 | Q6: Papel | R6: 1 | S6: 001 | T6: Manufactured Group Locally | U6: 1 | V6: 001 | W6: Bolsas de Papel | X6: 1 | Z6: RES | AA6: 1 | AB6: 1 | AC6: 1
A7: BLANCO SEIN 32 X 45 | B7: 0001BCO00005 | C7: 4 | D7: 0001BCO00005 | E7: .0000 | F7: 10.0000 | G7: .0000 | I7: Resmas | K7: 1 | L7: RES | M7: 007 | N7: 1 | O7: Papeles | P7: 001 | Q7: Papel | R7: 1 | S7: 001 | T7: Manufactured Group Locally | U7: 1 | V7: 001 | W7: Bolsas de Papel | X7: 1 | Z7: RES | AA7: 1 | AB7: 1 | AC7: 1
A8: BLANCO SEIN 52 X 72 | B8: 0001BCO00006 | C8: 5 | D8: 0001BCO00006 | E8: .0000 | F8: 10.0000 | G8: .0000 | I8: Resmas | K8: 1 | L8: RES | M8: 007 | N8: 1 | O8: Papeles | P8: 001 | Q8: Papel | R8: 1 | S8: 001 | T8: Manufactured Group Locally | U8: 1 | V8: 001 | W8: Bolsas de Papel | X8: 1 | Z8: RES | AA8: 1 | AB8: 1 | AC8: 1
A9: BLANCO SEIN 52 X 36 | B9: 0001BCO00007 | C9: 6 | D9: 0001BCO00007 | E9: .0000 | F9: 10.0000 | G9: .0000 | I9: Resmas | K9: 1 | L9: RES | M9: 007 | N9: 1 | O9: Papeles | P9: 001 | Q9: Papel | R9: 1 | S9: 001 | T9: Manufactured Group Locally | U9: 1 | V9: 001 | W9: Bolsas de Papel | X9: 1 | Z9: RES | AA9: 1 | AB9: 1 | AC9: 1
A10: BLANCO SEIN 26 X 36 | B10: 0001BCO00008 | C10: 7 | D10: 0001BCO00008 | E10: .0000 | F10: 10.0000 | G10: .0000 | I10: Resmas | K10: 1 | L10: RES | M10: 007 | N10: 1 | O10: Papeles | P10: 001 | Q10: Papel | R10: 1 | S10: 001 | T10: Manufactured Group Locally | U10: 1 | V10: 001 | W10: Bolsas de Papel | X10: 1 | Z10: RES | AA10: 1 | AB10: 1 | AC10: 1
A11: BLANCO SEIN 26 X 18 | B11: 0001BCO00009 | C11: 8 | D11: 0001BCO00009 | E11: .0000 | F11: 10.0000 | G11: .0000 | I11: Resmas | K11: 1 | L11: RES | M11: 007 | N11: 1 | O11: Papeles | P11: 001 | Q11: Papel | R11: 1 | S11: 001 | T11: Manufactured Group Locally | U11: 1 | V11: 001 | W11: Bolsas de Papel | X11: 1 | Z11: RES | AA11: 1 | AB11: 1 | AC11: 1
A12: BLANCO SEIN 58 X 81 | B12: 0001BCO00010 | C12: 9 | D12: 0001BCO00010 | E12: .0000 | F12: 10.0000 | G12: .0000 | I12: Resmas | K12: 1 | L12: RES | M12: 007 | N12: 1 | O12: Papeles | P12: 001 | Q12: Papel | R12: 1 | S12: 001 | T12: Manufactured Group Locally | U12: 1 | V12: 001 | W12: Bolsas de Papel | X12: 1 | Z12: RES | AA12: 1 | AB12: 1 | AC12: 1
A13: BLANCO SEIN 58 X 40 | B13: 0001BCO00011 | C13: 10 | D13: 0001BCO00011 | E13: .0000 | F13: 10.0000 | G13: .0000 | I13: Resmas | K13: 1 | L13: RES | M13: 007 | N13: 1 | O13: Papeles | P13: 001 | Q13: Papel | R13: 1 | S13: 001 | T13: Manufactured Group Locally | U13: 1 | V13: 001 | W13: Bolsas de Papel | X13: 1 | Z13: RES | AA13: 1 | AB13: 1 | AC13: 1
A14: BLANCO SEIN 9 X 13 PIZZERO | B14: 0001BCO00014 | C14: 11 | D14: 0001BCO00014 | E14: .0000 | F14: 10.0000 | G14: .0000 | I14: Resmas | K14: 1 | L14: RES | M14: 007 | N14: 1 | O14: Papeles | P14: 001 | Q14: Papel | R14: 1 | S14: 001 | T14: Manufactured Group Locally | U14: 1 | V14: 001 | W14: Bolsas de Papel | X14: 1 | Z14: RES | AA14: 1 | AB14: 1 | AC14: 1
A15: BLANCO SEIN 30 X 40 | B15: 0001BCO00015 | C15: 12 | D15: 0001BCO00015 | E15: .0000 | F15: 10.0000 | G15: .0000 | I15: Resmas | K15: 1 | L15: RES | M15: 007 | N15: 1 | O15: Papeles | P15: 001 | Q15: Papel | R15: 1 | S15: 001 | T15: Manufactured Group Locally | U15: 1 | V15: 001 | W15: Bolsas de Papel | X15: 1 | Z15: RES | AA15: 1 | AB15: 1 | AC15: 1
... A30: KRAFT PURO 80 GRS. | B30: 0001KPU00080 | C30: 27 | D30: 0001KPU00080 | E30: .0000 | F30: 1.0000 | G30: .0000 | I30: Kilogramos | K30: 1 | L30: KG | M30: 007 | N30: 1 | O30: Papeles | P30: 001 | Q30: Papel | R30: 1 | S30: 001 | T30: Manufactured Group Locally | U30: 1 | V30: 001 | W30: Bolsas de Papel | X30: 1 | Z30: KG | AA30: 1 | AB30: 1 | AC30: 1
A31: KRAFT PURO 125 GRS. | B31: 0001KPU00125 | C31: 28 | D31: 0001KPU00125 | E31: .0000 | F31: 1.0000 | G31: .0000 | I31: Kilogramos | K31: 1 | L31: KG | M31: 007 | N31: 1 | O31: Papeles | P31: 001 | Q31: Papel | R31: 1 | S31: 001 | T31: Manufactured Group Locally | U31: 1 | V31: 001 | W31: Bolsas de Papel | X31: 1 | Z31: KG | AA31: 1 | AB31: 1 | AC31: 1 | AE31: 2025-05-21-00.00.00.000000
A32: KRAFT SEIN EN HOJAS 50 GRS. | B32: 0001KSE00001 | C32: 29 | D32: 0001KSE00001 | E32: .0000 | F32: 1.0000 | G32: .0000 | I32: Kilogramos | K32: 1 | L32: KG | M32: 007 | N32: 1 | O32: Papeles | P32: 001 | Q32: Papel | R32: 1 | S32: 001 | T32: Manufactured Group Locally | U32: 1 | V32: 001 | W32: Bolsas de Papel | X32: 1 | Z32: KG | AA32: 1 | AB32: 1 | AC32: 1
A33: KRAFT SEIN EN HOJAS 80 GRS. | B33: 0001KSE00002 | C33: 30 | D33: 0001KSE00002 | E33: .0000 | F33: 1.0000 | G33: .0000 | I33: Kilogramos | K33: 1 | L33: KG | M33: 007 | N33: 1 | O33: Papeles | P33: 001 | Q33: Papel | R33: 1 | S33: 001 | T33: Manufactured Group Locally | U33: 1 | V33: 001 | W33: Bolsas de Papel | X33: 1 | Z33: KG | AA33: 1 | AB33: 1 | AC33: 1
A34: DESMOLDANTE 30 X 40 | B34: 0002DES03040 | C34: 31 | D34: 0002DES03040 | E34: .0000 | F34: 5.0000 | G34: .0000 | I34: Resmas | K34: 1 | L34: RES | M34: 007 | N34: 1 | O34: Papeles | P34: 001 | Q34: Papel | R34: 1 | S34: 001 | T34: Manufactured Group Locally | U34: 1 | V34: 059 | W34: Papel en Hojas | X34: 1 | Z34: RES | AA34: 1 | AB34: 1 | AC34: 1 | AE34: 2025-05-21-00.00.00.000000
A35: DESMOLDANTE 32 X 30 | B35: 0002DES03230 | C35: 32 | D35: 0002DES03230 | E35: .0000 | F35: 5.0000 | G35: .0000 | I35: Resmas | K35: 1 | L35: RES | M35: 007 | N35: 1 | O35: Papeles | P35: 001 | Q35: Papel | R35: 1 | S35: 001 | T35: Manufactured Group Locally | U35: 1 | V35: 059 | W35: Papel en Hojas | X35: 1 | Z35: RES | AA35: 1 | AB35: 1 | AC35: 1 | AE35: 2024-04-11-00.00.00.000000
A36: DESMOLDANTE 32 X 46 | B36: 0002DES03246 | C36: 33 | D36: 0002DES03246 | E36: .0000 | F36: 5.0000 | G36: .0000 | I36: Resmas | K36: 1 | L36: RES | M36: 007 | N36: 1 | O36: Papeles | P36: 001 | Q36: Papel | R36: 1 | S36: 001 | T36: Manufactured Group Locally | U36: 1 | V36: 059 | W36: Papel en Hojas | X36: 1 | Z36: RES | AA36: 1 | AB36: 1 | AC36: 1
A37: DESMOLDANTE 40 X 60 | B37: 0002DES04060 | C37: 34 | D37: 0002DES04060 | E37: .0000 | F37: 5.0000 | G37: .0000 | I37: Resmas | K37: 1 | L37: RES | M37: 007 | N37: 1 | O37: Papeles | P37: 001 | Q37: Papel | R37: 1 | S37: 001 | T37: Manufactured Group Locally | U37: 1 | V37: 059 | W37: Papel en Hojas | X37: 1 | Z37: RES | AA37: 1 | AB37: 1 | AC37: 1
A38: DESMOLDANTE 45 X 70 | B38: 0002DES04565 | C38: 35 | D38: 0002DES04565 | E38: .0000 | F38: 5.0000 | G38: .0000 | I38: Resmas | K38: 1 | L38: RES | M38: 007 | N38: 1 | O38: Papeles | P38: 001 | Q38: Papel | R38: 1 | S38: 001 | T38: Manufactured Group Locally | U38: 1 | V38: 001 | W38: Bolsas de Papel | X38: 1 | Z38: RES | AA38: 1 | AB38: 1 | AC38: 1
A39: DESMOLDANTE 60 X 80 | B39: 0002DES06080 | C39: 36 | D39: 0002DES06080 | E39: .0000 | F39: 5.0000 | G39: .0000 | I39: Unidades | K39: 1 | L39: UN | M39: 007 | N39: 1 | O39: Papeles | P39: 001 | Q39: Papel | R39: 1 | S39: 001 | T39: Manufactured Group Locally | U39: 1 | V39: 059 | W39: Papel en Hojas | X39: 1 | Z39: UN | AA39: 1 | AB39: 1 | AC39: 1
A40: DESMOLDANTE 70 X 90 | B40: 0002DES07090 | C40: 37 | D40: 0002DES07090 | E40: .0000 | F40: 5.0000 | G40: .0000 | I40: Resmas | K40: 1 | L40: RES | M40: 007 | N40: 1 | O40: Papeles | P40: 001 | Q40: Papel | R40: 1 | S40: 001 | T40: Manufactured Group Locally | U40: 1 | V40: 001 | W40: Bolsas de Papel | X40: 1 | Z40: RES | AA40: 1 | AB40: 1 | AC40: 1
A41: SEDA BLANCO 75 X 100 (400 H) | B41: 0002SED75100 | C41: 38 | D41: 0002SED75100 | E41: .0000 | F41: 10.0000 | G41: .0000 | I41: Resmas | K41: 1 | L41: RES | M41: 007 | N41: 1 | O41: Papeles | P41: 001 | Q41: Papel | R41: 1 | S41: 001 | T41: Manufactured Group Locally | U41: 1 | V41: 001 | W41: Bolsas de Papel | X41: 1 | Z41: RES | AA41: 1 | AB41: 1 | AC41: 1 | AE41: 2025-05-22-00.00.00.000000
A42: BOBINA BLANCO SEIN 40 CM. | B42: 0003BCO00040 | C42: 39 | D42: 0003BCO00040 | E42: .0000 | F42: 1.0000 | G42: .0000 | I42: Kilogramos | K42: 1 | L42: KG | M42: 007 | N42: 1 | O42: Papeles | P42: 001 | Q42: Papel | R42: 1 | S42: 001 | T42: Manufactured Group Locally | U42: 1 | V42: 001 | W42: Bolsas de Papel | X42: 1 | Z42: KG | AA42: 1 | AB42: 1 | AC42: 1
A43: BOBINA BLANCO SEIN 60 CM. | B43: 0003BCO00060 | C43: 40 | D43: 0003BCO00060 | E43: .0000 | F43: 1.0000 | G43: .0000 | I43: Kilogramos | K43: 1 | L43: KG | M43: 007 | N43: 1 | O43: Papeles | P43: 001 | Q43: Papel | R43: 1 | S43: 001 | T43: Manufactured Group Locally | U43: 1 | V43: 001 | W43: Bolsas de Papel | X43: 1 | Z43: KG | AA43: 1 | AB43: 1 | AC43: 1
A44: BOBINA SULFITO PRIMERA 40 CM. | B44: 0003BCP00040 | C44: 41 | D44: 0003BCP00040 | E44: .0000 | F44: 1.0000 | G44: .0000 | I44: Kilogramos | K44: 1 | L44: KG | M44: 007 | N44: 1 | O44: Papeles | P44: 001 | Q44: Papel | R44: 1 | S44: 001 | T44: Manufactured Group Locally | U44: 1 | V44: 001 | W44: Bolsas de Papel | X44: 1 | Z44: KG | AA44: 1 | AB44: 1 | AC44: 1 | AE44: 2025-05-22-00.00.00.000000
A45: BOBINA SULFITO PRIMERA 60 CM. | B45: 0003BCP00060 | C45: 42 | D45: 0003BCP00060 | E45: .0000 | F45: 1.0000 | G45: .0000 | I45: Kilogramos | K45: 1 | L45: KG | M45: 007 | N45: 1 | O45: Papeles | P45: 001 | Q45: Papel | R45: 1 | S45: 001 | T45: Manufactured Group Locally | U45: 1 | V45: 001 | W45: Bolsas de Papel | X45: 1 | Z45: KG | AA45: 1 | AB45: 1 | AC45: 1 | AE45: 2025-05-22-00.00.00.000000
A46: BOBINA KRAFT 50 SEIN 40 CM. | B46: 0003KRA00040 | C46: 43 | D46: 0003KRA00040 | E46: .0000 | F46: 1.0000 | G46: .0000 | I46: Kilogramos | K46: 1 | L46: KG | M46: 007 | N46: 1 | O46: Papeles | P46: 001 | Q46: Papel | R46: 1 | S46: 001 | T46: Manufactured Group Locally | U46: 1 | V46: 001 | W46: Bolsas de Papel | X46: 1 | Z46: KG | AA46: 1 | AB46: 1 | AC46: 1 | AE46: 2025-05-22-00.00.00.000000
A47: BOBINA KRAFT 80 SEIN 40 CM. | B47: 0003KRA00041 | C47: 44 | D47: 0003KRA00041 | E47: .0000 | F47: 1.0000 | G47: .0000 | I47: Kilogramos | K47: 1 | L47: KG | M47: 007 | N47: 1 | O47: Papeles | P47: 001 | Q47: Papel | R47: 1 | S47: 001 | T47: Manufactured Group Locally | U47: 1 | V47: 001 | W47: Bolsas de Papel | X47: 1 | Z47: KG | AA47: 1 | AB47: 1 | AC47: 1 | AE47: 2025-05-22-00.00.00.000000
A48: BOBINA KRAFT 50 SEIN 60 CM. | B48: 0003KRA00060 | C48: 45 | D48: 0003KRA00060 | E48: .0000 | F48: 1.0000 | G48: .0000 | I48: Kilogramos | K48: 1 | L48: KG | M48: 007 | N48: 1 | O48: Papeles | P48: 001 | Q48: Papel | R48: 1 | S48: 001 | T48: Manufactured Group Locally | U48: 1 | V48: 001 | W48: Bolsas de Papel | X48: 1 | Z48: KG | AA48: 1 | AB48: 1 | AC48: 1 | AE48: 2025-05-22-00.00.00.000000
A49: BOBINA KRAFT 80 SEIN 60 CM. | B49: 0003KRA00061 | C49: 46 | D49: 0003KRA00061 | E49: .0000 | F49: 1.0000 | G49: .0000 | I49: Kilogramos | K49: 1 | L49: KG | M49: 007 | N49: 1 | O49: Papeles | P49: 001 | Q49: Papel | R49: 1 | S49: 001 | T49: Manufactured Group Locally | U49: 1 | V49: 001 | W49: Bolsas de Papel | X49: 1 | Z49: KG | AA49: 1 | AB49: 1 | AC49: 1 | AE49: 2025-05-22-00.00.00.000000
A50: BOBINA KRAFT 80 SEIN 80 CM. | B50: 0003KRA00081 | C50: 47 | D50: 0003KRA00081 | E50: .0000 | F50: 1.0000 | G50: .0000 | I50: Kilogramos | K50: 1 | L50: KG | M50: 007 | N50: 1 | O50: Papeles | P50: 001 | Q50: Papel | R50: 1 | S50: 001 | T50: Manufactured Group Locally | U50: 1 | V50: 001 | W50: Bolsas de Papel | X50: 1 | Z50: KG | AA50: 1 | AB50: 1 | AC50: 1 | AE50: 2025-05-22-00.00.00.000000
A51: PAPEL SEPARADOR PARA PICADA 11CM | B51: 0003PER00011 | C51: 904 | D51: 0003PER00011 | E51: .0000 | F51: 5.0000 | G51: .0000 | I51: Unidades | K51: 1 | L51: UN | M51: 007 | N51: 1 | O51: Papeles | P51: 001 | Q51: Papel | R51: 1 | S51: 001 | T51: Manufactured Group Locally | U51: 1 | V51: 001 | W51: Bolsas de Papel | X51: 1 | Z51: UN | AA51: 1 | AB51: 1 | AC51: 1
A52: BSAS KRAFT Nº 2L | B52: 0004KRA0002L | C52: 48 | D52: 0004KRA0002L | E52: .0000 | F52: 4.3000 | G52: .0000 | I52: Paquetes | K52: 1 | L52: PAQ | M52: 007 | N52: 1 | O52: Papeles | P52: 001 | Q52: Papel | R52: 1 | S52: 001 | T52: Manufactured Group Locally | U52: 1 | V52: 001 | W52: Bolsas de Papel | X52: 1 | Z52: PAQ | AA52: 1000 | AB52: 1000 | AC52: 1
A53: BSAS KRAFT Nº 3 | B53: 0004KRA0003C | C53: 49 | D53: 0004KRA0003C | E53: .0000 | F53: 4.8500 | G53: .0000 | I53: Paquetes | K53: 1 | L53: PAQ | M53: 007 | N53: 1 | O53: Papeles | P53: 001 | Q53: Papel | R53: 1 | S53: 001 | T53: Manufactured Group Locally | U53: 1 | V53: 001 | W53: Bolsas de Papel | X53: 1 | Z53: PAQ | AA53: 1000 | AB53: 1000 | AC53: 1
A54: BSAS KRAFT Nº 3L | B54: 0004KRA0003L | C54: 50 | D54: 0004KRA0003L | E54: .0000 | F54: 5.6500 | G54: .0000 | I54: Paquetes | K54: 1 | L54: PAQ | M54: 007 | N54: 1 | O54: Papeles | P54: 001 | Q54: Papel | R54: 1 | S54: 001 | T54: Manufactured Group Locally | U54: 1 | V54: 001 | W54: Bolsas de Papel | X54: 1 | Z54: PAQ | AA54: 1000 | AB54: 1000 | AC54: 1
A55: BSAS KRAFT Nº 4A | B55: 0004KRA0004A | C55: 51 | D55: 0004KRA0004A | E55: .0000 | F55: 6.5000 | G55: .0000 | I55: Paquetes | K55: 1 | L55: PAQ | M55: 007 | N55: 1 | O55: Papeles | P55: 001 | Q55: Papel | R55: 1 | S55: 001 | T55: Manufactured Group Locally | U55: 1 | V55: 001 | W55: Bolsas de Papel | X55: 1 | Z55: PAQ | AA55: 1000 | AB55: 1000 | AC55: 1
...

Sheet Papeles-Cartulina
B2: LISTA DE PRECIOS de 26 DE OCTUBRE 2026 (B18)
B3: COMPAÑÍA LA PILARICA S. A. - DARNEL WWW.DARNELGROUP.COM
B4: CODIGO PILARICA | C4: CODIGO DARNEL | D4: U/M | E4: C/U | F4: DESCRIPCION | G4: COMENTARIO | H4: PRECIO
B5: PAPEL BIOXIDO Y DESMOLDANTE | P5: Marca | Q5: Modelo | R5: Código | S5: Ducha | T5: Bidet | U5: Lavatorio
B6: 0001BIO00002 | D6: kg | E6: 1 | F6: BIOXIDO 75 X 50 | G6: Resma 10 KG. | H6: =_xlfn.XLOOKUP(B6,lista!A:A,lista!C:C,0,0) -> 72428
B7: 0001BIO00004 | D7: kg | E7: 1 | F7: BIOXIDO 37 X 50 | G7: Resma 10 KG. | H7: =_xlfn.XLOOKUP(B7,lista!A:A,lista!C:C,0,0) -> 72428 | P7: FV | Q7: Puelo | R7: 0310/B5-CR | S7: 2
B8: 0001BIO00008 | D8: kg | E8: 1 | F8: BIOXIDO 37 X 25 | G8: Resma 10 KG. | H8: =_xlfn.XLOOKUP(B8,lista!A:A,lista!C:C,0,0) -> 72428 | P8: FV | Q8: Puelo | R8: 0181.01/B5-CR | U8: 1
B9: 0001BIO00016 | D9: kg | E9: 1 | F9: BIOXIDO 18 X 25 | G9: Resma 10 KG. | H9: =_xlfn.XLOOKUP(B9,lista!A:A,lista!C:C,0,0) -> 72428 | P9: FV | Q9: Puelo | R9: 0106/B5-CR | S9: 1
B10: 0002DES03246 | D10: res | E10: 1 | F10: DESMOLDANTE 32 X 46 | G10: Resma 5 KG. | H10: =_xlfn.XLOOKUP(B10,lista!A:A,lista!C:C,0,0) -> 64589 | P10: FV | Q10: Puelo | R10: 0189/B5 | T10: 1
B11: 0002DES04060 | D11: res | E11: 1 | F11: DESMOLDANTE 40 X 60 | G11: Resma 5 KG. | H11: =_xlfn.XLOOKUP(B11,lista!A:A,lista!C:C,0,0) -> 64589 | P11: FV | Q11: Libby | R11: 0206/39 | U11: 1
B12: 0002DES04565 | D12: res | E12: 1 | F12: DESMOLDANTE 45 X 64 | G12: Resma 5 KG. | H12: =_xlfn.XLOOKUP(B12,lista!A:A,lista!C:C,0,0) -> 64589 | P12: FV | Q12: Coty | R12: 0106/D9 | S12: 1
B13: 0002DES06080 | D13: res | E13: 1 | F13: DESMOLDANTE 60 X 80 | G13: Resma 5 KG. | H13: =_xlfn.XLOOKUP(B13,lista!A:A,lista!C:C,0,0) -> 64589 | P13: FV | Q13: Coty | R13: 0189/D9 | T13: 1
B14: 0002DES07090 | D14: res | E14: 1 | F14: DESMOLDANTE 70 X 90 | G14: Resma 5 KG. | H14: =_xlfn.XLOOKUP(B14,lista!A:A,lista!C:C,0,0) -> 64589 | P14: FV | Q14: Coty | R14: 0181.02/D9 | U14: 2
B15: PAPEL PARAFINADO | R15: Total | S15: =SUM(S7:S14) -> 4 | T15: =SUM(T7:T14) -> 2 | U15: =SUM(U7:U14) -> 4
B16: 0082ALL00009 | D16: res | E16: 1 | F16: PAPEL PARAFINADO LISO 40 x 40 cm | G16: Resma 1 KG. | H16: =_xlfn.XLOOKUP(B16,lista!A:A,lista!C:C,0,0) -> 12994
B17: 0082ALL00020 | D17: res | E17: 1 | F17: PAPEL PARAFINADO LISO 35 x 40 cm | G17: Resma 5 KG. | H17: =_xlfn.XLOOKUP(B17,lista!A:A,lista!C:C,0,0) -> 64439
B18: 0082ALL00021 | D18: res | E18: 1 | F18: PAPEL PARAFINADO GENERICO 35 x 40 cm | G18: Resma 5 KG. | H18: =_xlfn.XLOOKUP(B18,lista!A:A,lista!C:C,0,0) -> 64566
B19: 0082ALL00022 | D19: res | E19: 1 | F19: PAPEL PARAFINADO PERSONALIZADO | G19: Resma 5 KG. | H19: =_xlfn.XLOOKUP(B19,lista!A:A,lista!C:C,0,0) -> 64276
B20: PAPEL ALUMINIZADO
B21: 0082ALL00002 | D21: res | E21: 1 | F21: PAPEL ALUMINIO IMPRESO GENERICO 25 x 35 cm | G21: Resma 5 KG. | H21: =_xlfn.XLOOKUP(B21,lista!A:A,lista!C:C,0,0) -> 125496
B22: 0082ALL00003 | D22: res | E22: 1 | F22: PAPEL ALUMINIO PERSONALIZADO | G22: Resma 5 KG. | H22: =_xlfn.XLOOKUP(B22,lista!A:A,lista!C:C,0,0) -> 125185
B23: 0082ALL00004 | D23: res | E23: 1 | F23: PAPEL ALUMINIO LISO 25 x 35 cm | G23: Resma 5 KG. | H23: =_xlfn.XLOOKUP(B23,lista!A:A,lista!C:C,0,0) -> 126192
B24: 0082ALL00005 | D24: res | E24: 1 | F24: PAPEL ALUMINIO LISO 34 x 50 cm | G24: Resma 5 KG. | H24: =_xlfn.XLOOKUP(B24,lista!A:A,lista!C:C,0,0) -> 126192
B25: 0082ALL00006 | D25: res | E25: 1 | F25: PAPEL ALUMINIO IMPRESO GENERICO 34 x 50 cm | G25: Resma 5 KG. | H25: =_xlfn.XLOOKUP(B25,lista!A:A,lista!C:C,0,0) -> 125844
B26: CARTON - CARTULINA ANTIGRASA
B27: 0018DARBB0026 | C27: RPN02026101XC | D27: caja | E27: 200 | F27: CAJA PARA ALIMENTOS DARNEL NATURAL 26 Oz BLANCA PAQX50 Un. | G27: Nuevo | H27: =_xlfn.XLOOKUP(B27,lista!A:A,lista!C:C,0,0) -> 47151
B28: 0018DARBK0026 | C28: =_xlfn.XLOOKUP('Papeles-Cartulina'!B28,amb!B:B,amb!D:D,0,0) -> RPN02026102XC | D28: =_xlfn.XLOOKUP('Papeles-Cartulina'!B28,amb!B:B,amb!L:L,0,0) -> PAQ | E28: =_xlfn.XLOOKUP(B28,amb!B:B,amb!AA:AA,0,0) -> 200 | F28: =_xlfn.XLOOKUP(B28,amb!B:B,amb!A:A,0,0) -> CAJA PARA ALIMENTOS DARNEL NATURAL 26 Oz MOCA PAQX50 CAJ X200UNID | G28: Nuevo | H28: =_xlfn.XLOOKUP(B28,lista!A:A,lista!C:C,0,0) -> 43116
B29: 0018DARBB0045 | C29: =_xlfn.XLOOKUP('Papeles-Cartulina'!B29,amb!B:B,amb!D:D,0,0) -> RPN02045101XC | D29: =_xlfn.XLOOKUP('Papeles-Cartulina'!B29,amb!B:B,amb!L:L,0,0) -> PAQ | E29: =_xlfn.XLOOKUP(B29,amb!B:B,amb!AA:AA,0,0) -> 200 | F29: =_xlfn.XLOOKUP(B29,amb!B:B,amb!A:A,0,0) -> CAJA PARA ALIMENTOS DARNEL NATURAL 45 Oz BLANCO PQX50 CJX200 | G29: Nuevo | H29: =_xlfn.XLOOKUP(B29,lista!A:A,lista!C:C,0,0) -> 68591
B30: 0018DARBKS045 | C30: =_xlfn.XLOOKUP('Papeles-Cartulina'!B30,amb!B:B,amb!D:D,0,0) -> RPN02045102XTE | D30: =_xlfn.XLOOKUP('Papeles-Cartulina'!B30,amb!B:B,amb!L:L,0,0) -> PAQ | E30: =_xlfn.XLOOKUP(B30,amb!B:B,amb!AA:AA,0,0) -> 200 | F30: =_xlfn.XLOOKUP(B30,amb!B:B,amb!A:A,0,0) -> CAJA ALIMENTOS SAFETYPLUS DARNEL NATURALS 45 Oz MOCA PQX50 CAJX200 | G30: Nuevo | H30: =_xlfn.XLOOKUP(B30,lista!A:A,lista!C:C,0,0) -> 67623
B31: 0018DARBB0049 | C31: =_xlfn.XLOOKUP('Papeles-Cartulina'!B31,amb!B:B,amb!D:D,0,0) -> RPN02049101XC | D31: =_xlfn.XLOOKUP('Papeles-Cartulina'!B31,amb!B:B,amb!L:L,0,0) -> PAQ | E31: =_xlfn.XLOOKUP(B31,amb!B:B,amb!AA:AA,0,0) -> 200 | F31: =_xlfn.XLOOKUP(B31,amb!B:B,amb!A:A,0,0) -> CAJA PARA ALIMENTOS DARNEL NATURALS 49 Oz BLANCO PQX50 CAJX200 | G31: Nuevo | H31: =_xlfn.XLOOKUP(B31,lista!A:A,lista!C:C,0,0) -> 73442
B32: 0018DARBK0049 | C32: =_xlfn.XLOOKUP('Papeles-Cartulina'!B32,amb!B:B,amb!D:D,0,0) -> RPN02049102XC | D32: =_xlfn.XLOOKUP('Papeles-Cartulina'!B32,amb!B:B,amb!L:L,0,0) -> PAQ | E32: =_xlfn.XLOOKUP(B32,amb!B:B,amb!AA:AA,0,0) -> 200 | F32: =_xlfn.XLOOKUP(B32,amb!B:B,amb!A:A,0,0) -> CAJA PARA ALIMENTOS DARNEL NATURAL 49 Oz MOCA PQX50 CJX200 | G32: Nuevo | H32: =_xlfn.XLOOKUP(B32,lista!A:A,lista!C:C,0,0) -> 67949
B33: 0018DARBB0066 | C33: =_xlfn.XLOOKUP('Papeles-Cartulina'!B33,amb!B:B,amb!D:D,0,0) -> RPN02066101XC | D33: =_xlfn.XLOOKUP('Papeles-Cartulina'!B33,amb!B:B,amb!L:L,0,0) -> PAQ | E33: =_xlfn.XLOOKUP(B33,amb!B:B,amb!AA:AA,0,0) -> 200 | F33: =_xlfn.XLOOKUP(B33,amb!B:B,amb!A:A,0,0) -> CAJA PARA ALIMENTOS DARNEL NATURAL 66 Oz BLANCO PQX50 CJX200 | G33: Nuevo | H33: =_xlfn.XLOOKUP(B33,lista!A:A,lista!C:C,0,0) -> 80488
B34: 0018DARBK0066 | C34: =_xlfn.XLOOKUP('Papeles-Cartulina'!B34,amb!B:B,amb!D:D,0,0) -> RPN02066102XC | D34: =_xlfn.XLOOKUP('Papeles-Cartulina'!B34,amb!B:B,amb!L:L,0,0) -> PAQ | E34: =_xlfn.XLOOKUP(B34,amb!B:B,amb!AA:AA,0,0) -> 200 | F34: =_xlfn.XLOOKUP(B34,amb!B:B,amb!A:A,0,0) -> CAJA PARA ALIMENTOS DARNEL NATURAL 66 Oz MOCA PQX50 CJX200 | G34: Nuevo | H34: =_xlfn.XLOOKUP(B34,lista!A:A,lista!C:C,0,0) -> 74222
B35: 0018DARBB0072 | C35: =_xlfn.XLOOKUP('Papeles-Cartulina'!B35,amb!B:B,amb!D:D,0,0) -> RPN0207201X | D35: =_xlfn.XLOOKUP('Papeles-Cartulina'!B35,amb!B:B,amb!L:L,0,0) -> PAQ | E35: =_xlfn.XLOOKUP(B35,amb!B:B,amb!AA:AA,0,0) -> 100 | F35: =_xlfn.XLOOKUP(B35,amb!B:B,amb!A:A,0,0) -> CAJA PARA ALIMENTOS DARNEL NATURALS 72 Oz BLANCO BLX100 | G35: Nuevo | H35: =_xlfn.XLOOKUP(B35,lista!A:A,lista!C:C,0,0) -> 50051
B36: 0018DARBBK072 | C36: =_xlfn.XLOOKUP('Papeles-Cartulina'!B36,amb!B:B,amb!D:D,0,0) -> RPN0207202X | D36: =_xlfn.XLOOKUP('Papeles-Cartulina'!B36,amb!B:B,amb!L:L,0,0) -> PAQ | E36: =_xlfn.XLOOKUP(B36,amb!B:B,amb!AA:AA,0,0) -> 100 | F36: =_xlfn.XLOOKUP(B36,amb!B:B,amb!A:A,0,0) -> CAJA PARA ALIMENTOS DARNEL NATURALS 72 Oz MOCA BLX100 | G36: Nuevo | H36: =_xlfn.XLOOKUP(B36,lista!A:A,lista!C:C,0,0) -> 50375
B37: 0018DARBB0115 | C37: =_xlfn.XLOOKUP('Papeles-Cartulina'!B37,amb!B:B,amb!D:D,0,0) -> RPN02011501X | D37: =_xlfn.XLOOKUP('Papeles-Cartulina'!B37,amb!B:B,amb!L:L,0,0) -> PAQ | E37: =_xlfn.XLOOKUP(B37,amb!B:B,amb!AA:AA,0,0) -> 100 | F37: =_xlfn.XLOOKUP(B37,amb!B:B,amb!A:A,0,0) -> CAJA PARA ALIMENTOS DARNEL NATURALS 115 Oz BLANCO BLX100 UNID | G37: Nuevo | H37: 43095
B38: 0018DARBBK115 | C38: RPN02011502X | D38: caja | E38: 100 | F38: CAJA PARA ALIMENTOS DARNEL NATURAL 115oz MOCA | G38: Nuevo | H38: 43428
B39: CAJAS y ESTUCHES PARA PAPAS FRITAS
B40: 0018DARBBF0001 | C40: =_xlfn.XLOOKUP('Papeles-Cartulina'!B40,amb!B:B,amb!D:D,0,0) -> RPN02P08201X | D40: =_xlfn.XLOOKUP('Papeles-Cartulina'!B40,amb!B:B,amb!L:L,0,0) -> PAQ | E40: =_xlfn.XLOOKUP(B40,amb!B:B,amb!AA:AA,0,0) -> 600 | F40: =_xlfn.XLOOKUP(B40,amb!B:B,amb!A:A,0,0) -> CAJA PEQUEÑA PARA PAPAS FRITAS DARNEL NATURAL BLANCA PQX100 CJX600 | G40: Nuevo | H40: =_xlfn.XLOOKUP(B40,lista!A:A,lista!C:C,0,0) -> 33056
B41: 0018DARBBF0005 | C41: =_xlfn.XLOOKUP('Papeles-Cartulina'!B41,amb!B:B,amb!D:D,0,0) -> RPN02P08701X | D41: =_xlfn.XLOOKUP('Papeles-Cartulina'!B41,amb!B:B,amb!L:L,0,0) -> PAQ | E41: =_xlfn.XLOOKUP(B41,amb!B:B,amb!AA:AA,0,0) -> 600 | F41: =_xlfn.XLOOKUP(B41,amb!B:B,amb!A:A,0,0) -> CAJA MEDIANA PARA PAPAS FRITAS DARNEL NATURAL BLANCO PQX100 CJX600 | G41: Nuevo | H41: =_xlfn.XLOOKUP(B41,lista!A:A,lista!C:C,0,0) -> 60322
...

Sheet LISTA 22.09.2025
A1: VEN2140-Cons. Precios de venta
A3: Articulo | B3: Nombre | C3: U.M. | D3: Lista | E3: Precio Actual | F3: Vigencia hasta | G3: Conimpuesto | H3: Fecha act. | I3: Moneda | J3: Precio Actual | K3: MonedaAnterior | L3: PrecioAnterior | M3: Variación Absoluta | N3: Variación Porcentual | O3: LINEA | P3: MATERIAL DE PRODUCTOS | Q3: TIPO DE MANUFACTURA | R3: FAMILIA DE PRODUCTOS | S3: CANTIDAD X UM | T3: POSICION ARANCELARIA
A4: 0001BCO00002 | B4: BLANCO SEIN 40 X 50 | C4: RES | D4: 1, LISTA GENERAL | E4: 27785 | F4: 219512 | G4: 0 | H4: 45897 | I4: PS | J4: 27785 | K4: PS | L4: 25727 | M4: 2058 | N4: 8 | O4: 007, Papeles | P4: 001, Papel | Q4: 001, Manufactured Group Locall | R4: 001, Bolsas de Papel | S4: 1, 1 | T4: P01, 480256
A5: 0001BCO00003 | B5: BLANCO SEIN 64 X 90 | C5: RES | D5: 1, LISTA GENERAL | E5: 27785 | F5: 219512 | G5: 0 | H5: 45897 | I5: PS | J5: 27785 | K5: PS | L5: 25727 | M5: 2058 | N5: 8 | O5: 007, Papeles | P5: 001, Papel | Q5: 001, Manufactured Group Locall | R5: 001, Bolsas de Papel | S5: 1, 1 | T5: P01, 480256
A6: 0001BCO00004 | B6: BLANCO SEIN 64 X 45 | C6: RES | D6: 1, LISTA GENERAL | E6: 27785 | F6: 219512 | G6: 0 | H6: 45897 | I6: PS | J6: 27785 | K6: PS | L6: 25727 | M6: 2058 | N6: 8 | O6: 007, Papeles | P6: 001, Papel | Q6: 001, Manufactured Group Locall | R6: 001, Bolsas de Papel | S6: 1, 1 | T6: P01, 480256
A7: 0001BCO00005 | B7: BLANCO SEIN 32 X 45 | C7: RES | D7: 1, LISTA GENERAL | E7: 27785 | F7: 219512 | G7: 0 | H7: 45897 | I7: PS | J7: 27785 | K7: PS | L7: 25727 | M7: 2058 | N7: 8 | O7: 007, Papeles | P7: 001, Papel | Q7: 001, Manufactured Group Locall | R7: 001, Bolsas de Papel | S7: 1, 1 | T7: P01, 480256
A8: 0001BCO00006 | B8: BLANCO SEIN 52 X 72 | C8: RES | D8: 1, LISTA GENERAL | E8: 27785 | F8: 219512 | G8: 0 | H8: 45897 | I8: PS | J8: 27785 | K8: PS | L8: 25727 | M8: 2058 | N8: 8 | O8: 007, Papeles | P8: 001, Papel | Q8: 001, Manufactured Group Locall | R8: 001, Bolsas de Papel | S8: 1, 1 | T8: P01, 480256
A9: 0001BCO00007 | B9: BLANCO SEIN 52 X 36 | C9: RES | D9: 1, LISTA GENERAL | E9: 27785 | F9: 219512 | G9: 0 | H9: 45897 | I9: PS | J9: 27785 | K9: PS | L9: 25727 | M9: 2058 | N9: 8 | O9: 007, Papeles | P9: 001, Papel | Q9: 001, Manufactured Group Locall | R9: 001, Bolsas de Papel | S9: 1, 1 | T9: P01, 480256
A10: 0001BCO00008 | B10: BLANCO SEIN 26 X 36 | C10: RES | D10: 1, LISTA GENERAL | E10: 27785 | F10: 219512 | G10: 0 | H10: 45897 | I10: PS | J10: 27785 | K10: PS | L10: 25727 | M10: 2058 | N10: 8 | O10: 007, Papeles | P10: 001, Papel | Q10: 001, Manufactured Group Locall | R10: 001, Bolsas de Papel | S10: 1, 1 | T10: P01, 480256
A11: 0001BCO00009 | B11: BLANCO SEIN 26 X 18 | C11: RES | D11: 1, LISTA GENERAL | E11: 27785 | F11: 219512 | G11: 0 | H11: 45897 | I11: PS | J11: 27785 | K11: PS | L11: 25727 | M11: 2058 | N11: 8 | O11: 007, Papeles | P11: 001, Papel | Q11: 001, Manufactured Group Locall | R11: 001, Bolsas de Papel | S11: 1, 1 | T11: P01, 480256
A12: 0001BCO00010 | B12: BLANCO SEIN 58 X 81 | C12: RES | D12: 1, LISTA GENERAL | E12: 27785 | F12: 219512 | G12: 0 | H12: 45897 | I12: PS | J12: 27785 | K12: PS | L12: 25727 | M12: 2058 | N12: 8 | O12: 007, Papeles | P12: 001, Papel | Q12: 001, Manufactured Group Locall | R12: 001, Bolsas de Papel | S12: 1, 1 | T12: P01, 480256
A13: 0001BCO00011 | B13: BLANCO SEIN 58 X 40 | C13: RES | D13: 1, LISTA GENERAL | E13: 27785 | F13: 219512 | G13: 0 | H13: 45897 | I13: PS | J13: 27785 | K13: PS | L13: 25727 | M13: 2058 | N13: 8 | O13: 007, Papeles | P13: 001, Papel | Q13: 001, Manufactured Group Locall | R13: 001, Bolsas de Papel | S13: 1, 1 | T13: P01, 480256
A14: 0001BCO00014 | B14: BLANCO SEIN 9 X 13 PIZZERO | C14: RES | D14: 1, LISTA GENERAL | E14: 27785 | F14: 219512 | G14: 0 | H14: 45897 | I14: PS | J14: 27785 | K14: PS | L14: 25727 | M14: 2058 | N14: 8 | O14: 007, Papeles | P14: 001, Papel | Q14: 001, Manufactured Group Locall | R14: 001, Bolsas de Papel | S14: 1, 1 | T14: P01, 480256
A15: 0001BCO00015 | B15: BLANCO SEIN 30 X 40 | C15: RES | D15: 1, LISTA GENERAL | E15: 27785 | F15: 219512 | G15: 0 | H15: 45897 | I15: PS | J15: 27785 | K15: PS | L15: 25727 | M15: 2058 | N15: 8 | O15: 007, Papeles | P15: 001, Papel | Q15: 001, Manufactured Group Locall | R15: 001, Bolsas de Papel | S15: 1, 1 | T15: P01, 480256
... A71: 0005SER03333 | B71: SERVILLETA 33 X 33 | C71: CAJ | D71: 1, LISTA GENERAL | E71: 8972 | F71: 219512 | G71: 0 | H71: 45817 | I71: PS | J71: 8972 | K71: PS | L71: 9444 | M71: -472 | N71: -5 | O71: 007, Papeles | P71: 001, Papel | Q71: 003, Purchased from 3rd Party | R71: 002, Servilletas/Papel Cocina | S71: 1000, 1000 | T71: P07, 481830
A72: 0005SER10000 | B72: SERVILLETA (X 10.000) | C72: CAJ | D72: 1, LISTA GENERAL | E72: 3248 | F72: 219512 | G72: 0 | H72: 45352 | I72: PS | J72: 3248 | L72: 0 | M72: 3248 | N72: 0 | O72: 007, Papeles | P72: 001, Papel | Q72: 003, Purchased from 3rd Party | R72: 002, Servilletas/Papel Cocina | S72: 10000, 10000 | T72: P07, 481830
A73: 0005SERZ0001 | B73: SERVILLETAS DELIVERY ENSOBRADO x 2 (X 500) | C73: CAJ | D73: 1, LISTA GENERAL | E73: 21427 | F73: 219512 | G73: 0 | H73: 45919 | I73: PS | J73: 21427 | K73: PS | L73: 19131 | M73: 2296 | N73: 12 | O73: 007, Papeles | P73: 001, Papel | Q73: 003, Purchased from 3rd Party | R73: 002, Servilletas/Papel Cocina | S73: 500, 500 | T73: P07, 481830
A74: 0006BOR03441 | B74: CARPETA BORDADA 34X41 | C74: PAQ | D74: 1, LISTA GENERAL | E74: 7390 | F74: 219512 | G74: 0 | H74: 45762 | I74: PS | J74: 7390 | K74: PS | L74: 6718 | M74: 672 | N74: 10 | O74: 007, Papeles | P74: 001, Papel | Q74: 003, Purchased from 3rd Party | R74: 003, Moldes de Papel | S74: 100, 100 | T74: P08, 482390
A75: 0008MBI00016 | B75: MOLDE BIZCOCHUELO Nº 16 | C75: PAQ | D75: 1, LISTA GENERAL | E75: 33429 | F75: 219512 | G75: 0 | H75: 45817 | I75: PS | J75: 33429 | K75: PS | L75: 35188 | M75: -1759 | N75: -5 | O75: 007, Papeles | P75: 001, Papel | Q75: 003, Purchased from 3rd Party | R75: 003, Moldes de Papel | S75: 200, 200 | T75: P09, 482360
A76: 0008MBI00020 | B76: MOLDE BIZCOCHUELO Nº 20 | C76: PAQ | D76: 1, LISTA GENERAL | E76: 36634 | F76: 219512 | G76: 0 | H76: 45817 | I76: PS | J76: 36634 | K76: PS | L76: 37767 | M76: -1133 | N76: -3 | O76: 007, Papeles | P76: 001, Papel | Q76: 003, Purchased from 3rd Party | R76: 003, Moldes de Papel | S76: 200, 200 | T76: P09, 482360
A77: 0008MBI00022 | B77: MOLDE BIZCOCHUELO Nº 22 | C77: PAQ | D77: 1, LISTA GENERAL | E77: 41648 | F77: 219512 | G77: 0 | H77: 45762 | I77: PS | J77: 41648 | K77: PS | L77: 37862 | M77: 3786 | N77: 10 | O77: 007, Papeles | P77: 001, Papel | Q77: 003, Purchased from 3rd Party | R77: 003, Moldes de Papel | S77: 200, 200 | T77: P09, 482360
A78: 0008MRO00020 | B78: MOLDE ROSCA Nº 20 | C78: PAQ | D78: 1, LISTA GENERAL | E78: 21441 | F78: 219512 | G78: 0 | H78: 45817 | I78: PS | J78: 21441 | K78: PS | L78: 22569 | M78: -1128 | N78: -5 | O78: 007, Papeles | P78: 001, Papel | Q78: 003, Purchased from 3rd Party | R78: 003, Moldes de Papel | S78: 100, 100 | T78: P09, 482360
A79: 0008MRO00022 | B79: MOLDE ROSCA Nº 22 | C79: PAQ | D79: 1, LISTA GENERAL | E79: 26992 | F79: 219512 | G79: 0 | H79: 45762 | I79: PS | J79: 26992 | K79: PS | L79: 24538 | M79: 2454 | N79: 10 | O79: 007, Papeles | P79: 001, Papel | Q79: 003, Purchased from 3rd Party | R79: 003, Moldes de Papel | S79: 100, 100 | T79: P09, 482360
A80: 0008PIR00005 | B80: PIROTINES Nº 5 | C80: CAJ | D80: 1, LISTA GENERAL | E80: 6162 | F80: 219512 | G80: 0 | H80: 45762 | I80: PS | J80: 6162 | K80: PS | L80: 5602 | M80: 560 | N80: 10 | O80: 007, Papeles | P80: 001, Papel | Q80: 003, Purchased from 3rd Party | R80: 003, Moldes de Papel | S80: 1000, 1000 | T80: P09, 482360
A81: 0008PIR00010 | B81: PIROTINES Nº 10 | C81: CAJ | D81: 1, LISTA GENERAL | E81: 18143 | F81: 219512 | G81: 0 | H81: 45762 | I81: PS | J81: 18143 | K81: PS | L81: 16494 | M81: 1649 | N81: 10 | O81: 007, Papeles | P81: 001, Papel | Q81: 003, Purchased from 3rd Party | R81: 003, Moldes de Papel | S81: 1000, 1000 | T81: P09, 482360
A82: 0011PRI00003 | B82: CARTON BLANCO CIFIVE | C82: KG | D82: 1, LISTA GENERAL | E82: 2504 | F82: 219512 | G82: 0 | H82: 45817 | I82: PS | J82: 2504 | K82: PS | L82: 2782 | M82: -278 | N82: -9.99 | O82: 008, Cartón | P82: 001, Papel | Q82: 003, Purchased from 3rd Party | R82: 004, Carton en Hojas | S82: 1, 1 | T82: P10, 480442
A83: 0011SEG00030 | B83: CARTON GRIS Nº 30 | C83: KG | D83: 1, LISTA GENERAL | E83: 1387 | F83: 219512 | G83: 0 | H83: 45817 | I83: PS | J83: 1387 | K83: PS | L83: 1541 | M83: -154 | N83: -9.99 | O83: 008, Cartón | P83: 001, Papel | Q83: 003, Purchased from 3rd Party | R83: 004, Carton en Hojas | S83: 1, 1 | T83: P10, 480442
A84: 0011SEG00040 | B84: CARTON GRIS Nº 40 | C84: KG | D84: 1, LISTA GENERAL | E84: 1387 | F84: 219512 | G84: 0 | H84: 45817 | I84: PS | J84: 1387 | K84: PS | L84: 1541 | M84: -154 | N84: -9.99 | O84: 008, Cartón | P84: 001, Papel | Q84: 003, Purchased from 3rd Party | R84: 004, Carton en Hojas | S84: 1, 1 | T84: P10, 480442
... A90: 0012COM00006 | B90: BANDEJA DE CARTON Nº 6 21X29 | C90: PAQ | D90: 1, LISTA GENERAL | E90: 11530 | F90: 219512 | G90: 0 | H90: 45762 | I90: PS | J90: 11530 | K90: PS | L90: 10482 | M90: 1048 | N90: 10 | O90: 008, Cartón | P90: 001, Papel | Q90: 003, Purchased from 3rd Party | R90: 005, Bandejas de Papel / Carto | S90: 100, 100 | T90: P11, 482370
A91: 0012COM00051 | B91: BANDEJA KRAFT PURO N°1 (6PX100U) | C91: CAJ | D91: 1, LISTA GENERAL | E91: 15716 | F91: 219512 | G91: 0 | H91: 45897 | I91: PS | J91: 15716 | L91: 0 | M91: 15716 | N91: 0 | O91: 008, Cartón | P91: 001, Papel | Q91: 001, Manufactured Group Locall | R91: 005, Bandejas de Papel / Carto | S91: 600, 600 | T91: P11, 482370
A92: 0012COM00052 | B92: BANDEJA KRAFT PURO N°2 (6PX100U) | C92: CAJ | D92: 1, LISTA GENERAL | E92: 43825 | F92: 219512 | G92: 0 | H92: 45766 | I92: PS | J92: 43825 | K92: PS | L92: 48208 | M92: -4383 | N92: -9.09 | O92: 008, Cartón | P92: 001, Papel | Q92: 001, Manufactured Group Locall | R92: 005, Bandejas de Papel / Carto | S92: 600, 600 | T92: P11, 482370
A93: 0012COM00053 | B93: BANDEJA KRAFT PURO N°3 (4PX100U) | C93: CAJ | D93: 1, LISTA GENERAL | E93: 37089 | F93: 219512 | G93: 0 | H93: 45766 | I93: PS | J93: 37089 | K93: PS | L93: 40798 | M93: -3709 | N93: -9.09 | O93: 008, Cartón | P93: 001, Papel | Q93: 001, Manufactured Group Locall | R93: 005, Bandejas de Papel / Carto | S93: 400, 400 | T93: P11, 482370
A94: 0012COM00054 | B94: BANDEJA KRAFT PURO N°4 (2PX100U) | C94: CAJ | D94: 1, LISTA GENERAL | E94: 23042 | F94: 219512 | G94: 0 | H94: 45766 | I94: PS | J94: 23042 | K94: PS | L94: 25346 | M94: -2304 | N94: -9.09 | O94: 008, Cartón | P94: 001, Papel | Q94: 001, Manufactured Group Locall | R94: 005, Bandejas de Papel / Carto | S94: 200, 200 | T94: P11, 482370
A95: 0012COM10002 | B95: BANDEJA MICRO CORRUGADO N° 2 (4PX100U) | C95: CAJ | D95: 1, LISTA GENERAL | E95: 25792 | F95: 219512 | G95: 0 | H95: 45766 | I95: PS | J95: 25792 | K95: PS | L95: 28371 | M95: -2579 | N95: -9.09 | O95: 008, Cartón | P95: 001, Papel | Q95: 001, Manufactured Group Locall | R95: 005, Bandejas de Papel / Carto | S95: 400, 400 | T95: P11, 482370
A96: 0012COM10003 | B96: BANDEJA MICRO CORRUGADO N° 3 (4PX100U) | C96: CAJ | D96: 1, LISTA GENERAL | E96: 29631 | F96: 219512 | G96: 0 | H96: 45766 | I96: PS | J96: 29631 | K96: PS | L96: 32594 | M96: -2963 | N96: -9.09 | O96: 008, Cartón | P96: 001, Papel | Q96: 001, Manufactured Group Locall | R96: 005, Bandejas de Papel / Carto | S96: 400, 400 | T96: P11, 482370
A97: 0012COM10004 | B97: BANDEJA MICRO CORRUGADO N° 4 (4PX100U) | C97: CAJ | D97: 1, LISTA GENERAL | E97: 37337 | F97: 219512 | G97: 0 | H97: 45766 | I97: PS | J97: 37337 | K97: PS | L97: 41071 | M97: -3734 | N97: -9.09 | O97: 008, Cartón | P97: 001, Papel | Q97: 001, Manufactured Group Locall | R97: 005, Bandejas de Papel / Carto | S97: 400, 400 | T97: P11, 482370
A98: 0012COM10005 | B98: BANDEJA MICRO CORRUGADO N° 5 (2PX100U) | C98: CAJ | D98: 1, LISTA GENERAL | E98: 23204 | F98: 219512 | G98: 0 | H98: 45766 | I98: PS | J98: 23204 | K98: PS | L98: 25524 | M98: -2320 | N98: -9.09 | O98: 008, Cartón | P98: 001, Papel | Q98: 001, Manufactured Group Locall | R98: 005, Bandejas de Papel / Carto | S98: 200, 200 | T98: P11, 482370
A99: 0012COM10006 | B99: BANDEJA MICRO CORRUGADO N° 6 (4P X 50U) | C99: CAJ | D99: 1, LISTA GENERAL | E99: 20178 | F99: 219512 | G99: 0 | H99: 45766 | I99: PS | J99: 20178 | K99: PS | L99: 22196 | M99: -2018 | N99: -9.09 | O99: 008, Cartón | P99: 001, Papel | Q99: 001, Manufactured Group Locall | R99: 005, Bandejas de Papel / Carto | S99: 200, 200 | T99: P11, 482370
A100: 0012COM10012 | B100: BANDEJA MICRO CORRUGADO N°2 IMPRESA | C100: CAJ | D100: 1, LISTA GENERAL | E100: 37046 | F100: 219512 | G100: 0 | H100: 45919 | I100: PS | J100: 37046 | K100: PS | L100: 34622 | M100: 2424 | N100: 7 | O100: 008, Cartón | P100: 001, Papel | Q100: 001, Manufactured Group Locall | R100: 005, Bandejas de Papel / Carto | S100: 400, 400 | T100: P11, 482370
A101: 0012COM10013 | B101: BANDEJA MICRO CORRUGADO N°3 IMPRESA | C101: CAJ | D101: 1, LISTA GENERAL | E101: 42967 | F101: 219512 | G101: 0 | H101: 45919 | I101: PS | J101: 42967 | K101: PS | L101: 40156 | M101: 2811 | N101: 7 | O101: 008, Cartón | P101: 001, Papel | Q101: 001, Manufactured Group Locall | R101: 005, Bandejas de Papel / Carto | S101: 400, 400 | T101: P11, 482370
...

Sheet PVC
B2: LISTA DE PRECIOS de 26 DE OCTUBRE 2026 (B18)
B3: COMPAÑÍA LA PILARICA S. A. - DARNEL WWW.DARNELGROUP.COM
B4: CODIGO PILARICA | C4: CODIGO DARNEL | D4: U/M | E4: C/U | F4: DESCRIPCION | G4: COMENTARIO | H4: PRECIO
B5: FILM DE PVC
B6: PVC DARNEL 500 Mts.
B7: 0027LIG00030 | C7: SA135-300-500L | D7: Rollo | E7: 1 | F7: PVC 300mm (12") 300MM x 500 MTS. | H7: 13343
B8: 0027LIG00038 | C8: SA135-380-500L | D8: Rollo | E8: 1 | F8: PVC 380mm (15") 380MM x 500 MTS. | H8: 16489
B9: 0027LIG00045 | C9: SA135-450-500L | D9: Rollo | E9: 1 | F9: PVC 450mm (18") 450MM x 500 MTS. | H9: 19249
B10: PVC DARNEL 1000 Mts.
B11: 0027LIG01012 | C11: SA1D353001000 | D11: Rollo | E11: 1 | F11: PVC ECONO FILM 12" (300MM x 1000 MTS.) | H11: 23283
B12: 0027LIG01015 | C12: SA1D353801000 | D12: Rollo | E12: 1 | F12: PVC ECONO FILM 15" (380MM x 1000 MTS.) | H12: 29490
B13: 0027LIG01018 | C13: SA1D354501000 | D13: Rollo | E13: 1 | F13: PVC ECONO FILM 18" (450MM x 1000 MTS.) | H13: 34282
B14: PVC DARNEL 1400 Mts.
B15: 0027EST00012 | C15: SA1D35-300-1400 | D15: Rollo | E15: 1 | F15: PVC 12 " (300 MM X 1400 MTS.) | H15: =_xlfn.XLOOKUP(B15,lista!A:A,lista!C:C,0,0) -> 34508
B16: 0027EST00015 | C16: SA1D35-380-1400 | D16: Rollo | E16: 1 | F16: PVC 15 " (380MM X 1400 MTS.) | H16: =_xlfn.XLOOKUP(B16,lista!A:A,lista!C:C,0,0) -> 43780
B17: 0027EST00018 | C17: SA1D35-450-1400 | D17: Rollo | E17: 1 | F17: PVC 18 " (450MM X 1400 MTS.) | H17: =_xlfn.XLOOKUP(B17,lista!A:A,lista!C:C,0,0) -> 51888
B18: PVC LINEA TAMI
B19: 0027TAM28050 | C19: ST2-280-50R | D19: Rollo | E19: 1 | F19: PVC TAMI WRAP 280 MM X 50 MTS | G19: 35 unid./caja | H19: 1375
B20: 0027TAM28100 | C20: ST2-280-100R | D20: Rollo | E20: 1 | F20: PVC TAMI WRAP 280 MM X 100 MTS | G20: 24 unid./caja | H20: 2287
B21: PVC LINEA DOMESTICA
B22: 0027REP00282 | C22: ST3-280-200 | D22: Rollo | E22: 1 | F22: PVC REPUESTO 12" (300MM X 200 MTS) | G22: 15 unid./caja | H22: 4416
B23: 0027REP00382 | C23: ST3-380-200 | D23: Rollo | E23: 1 | F23: PVC REPUESTO 15" (380MM X 200 MTS) | G23: 15 Unid./caja | H23: 5733
B24: 0027REP00015 | C24: SD135-380-300R | D24: Rollo | E24: 1 | F24: PVC REPUESTO 15" (380MM X 300 MTS.) | G24: 12 unid./caja | H24: 9255
B25: 0027REP00030 | C25: SD135-380-300D | D25: Rollo | E25: 1 | F25: REPUESTO 15" (380MM X 300 MTS.) C/Dispenser | G25: 6 unid./caja | H25: 13184
B26: 0027REP00018 | C26: SD135-450-300DRB | D26: Rollo | E26: 1 | F26: PVC REPUESTO 18" (450MM X 300 MTS) | G26: 12 unid./caja | H26: 11297
B27: 0027REP00036 | C27: SD135-450-300D | D27: Rollo | E27: 1 | F27: PVC REPUESTO 18" (450mm X 300mts) C/Dispenser | G27: 6 unid./caja | H27: 14713
B28: PVC LINEA BIODEGRADABLE
B29: 0027BIO38100 | C29: SA4B35-380-1000 | D29: Rollo | E29: 1 | F29: PVC BIODEG. DARNEL 380MM X 1000 MTS | H29: 33577
B30: 0027BIO28100 | C30: SA4B31-280-100DR | D30: Rollo | E30: 1 | F30: PVC BIODEG. DARNEL 280MM X 100 MTS | G30: 24 unid./caja | H30: 2683
B31: 0027BIO28300 | C31: SA4B31-280-300D | D31: Rollo | E31: 1 | F31: PVC BIODEG DARNEL 280mm x 300 Mts C/Dispenser | G31: 6 unid./caja | H31: 9310
B32: LOS PRECIOS SON MAS IVA

Sheet Porta Comida XPS
B2: LISTA DE PRECIOS de 26 DE OCTUBRE 2026 (B18)
C3: COMPAÑÍA LA PILARICA S. A. - DARNEL WWW.DARNELGROUP.COM
B4: CODIGO PILARICA | C4: CODIGO DARNEL | D4: U/M | E4: C/U | F4: DESCRIPCION | G4: COMENTARIO | H4: PRECIO BULTO $
B5: PLATO TERMICO DE EXPANDIDO (MARMITAS)
B6: 0034CON00020 | C6: D742801RLFY | D6: paq | E6: 100 | F6: PLATO TERMICO C/TAPA R102 850ml (base/tapa) | G6: diam 190x50mm | H6: 24084
B7: 0034CON00021 | C7: D741701RY | D7: paq | E7: 100 | F7: PLATO TERMICO C/TAPA R100 500ml (base/tapa) | G7: diam 190x35mm | H7: 24509
B8: 0034CON00022 | C8: D744001RY | D8: paq | E8: 100 | F8: PLATO TERMICO C/TAPA R104 1200ml (base/tapa) | G8: diam 190x68mm | H8: 28822
B9: PLATOS ESPUMADOS
B10: 0034DARPWH05 | C10: D5105101NW | D10: caja | E10: 480 | F10: DARNEL PLATO HONDO BLANCO 5oz x 20u. | G10: Nuevo | H10: =_xlfn.XLOOKUP(B10,lista!A:A,lista!C:C,0,0) -> 15646
B11: 0034DARPW0015 | C11: D510601NW | D11: caja | E11: 480 | F11: DARNEL PLATO BLANCO 15,5 cm x 20u. | G11: Nuevo | H11: =_xlfn.XLOOKUP(B11,lista!A:A,lista!C:C,0,0) -> 22123
B12: 0034DARPW0023 | C12: D510901NW | D12: caja | E12: 480 | F12: DARNEL PLATO BLANCO 23 cm x 20u. | G12: Nuevo | H12: =_xlfn.XLOOKUP(B12,lista!A:A,lista!C:C,0,0) -> 43919
B13: ESTUCHES RECTANGULAR DE EXPANDIDO
B14: 0034DARP0001 | C14: NUEVO | D14: Bolson | E14: 200 | F14: PORTACOMIDA UY EXPANDIDO NR-J1 S/DIV x 200 un | G14: 230x160x60mm | H14: 28791
B15: 0034DARP0002 | C15: NUEVO | D15: Bolson | E15: 200 | F15: PORTACOMIDA UY EXPANDIDO NR-J2 C/DIV x 200 un | G15: 230x160x60mm | H15: 30819
B16: 0034DARP0011 | C16: NUEVO | D16: Bolson | E16: 200 | F16: PORTACOMIDA Uy EXPAND. NR-J1 BIO S/DIV x 200un | G16: 230x160x60mm | H16: 34510
B17: 0034DARP0022 | C17: NUEVO | D17: Bolson | E17: 200 | F17: PORTACOMIDA UY EXPAND. NR-J2 BIO C/DIV x 200un | G17: 230x160x60mm | H17: 36469
B18: ESTUCHES HAMBURGUESA DE EXPANDIDO
B19: 0034CON00017 | C19: D401101LNWCFY | D19: paq | E19: 400 | F19: ESTUCHE HAMBURGUESA CHICO G-1 | G19: 150x150x75mm | H19: 42029
B20: 0034CON00018 | C20: D402103CFY | D20: paq | E20: 400 | F20: ESTUCHE HAMBURGUESA GRANDE DH-03 | G20: 170x170x80mm | H20: 50045
B21: PORTA COMIDAS DE EXPANDIDO
B22: 0034CON00010 | C22: D7416015FY | D22: paq | E22: 400 | F22: BANDEJA TERMICA DM70 de 500ml (simil 102) | G22: 116x162x39mm | H22: 29616
B23: 0034CON00011 | C23: D7416015LTFY | D23: paq | E23: 400 | F23: TAPA PARA BAND. TERMICA DM70 de 500ml | G23: 130x170x10mm | H23: 22679
B24: 0034CON00012 | C24: D743001RFY | D24: paq | E24: 200 | F24: BANDEJA TERMICA DM90-A3 con 3 DIVIS 900ml | G24: 162x220x52mm | H24: 34952
B25: 0034CON00013 | C25: D743401RFY | D25: paq | E25: 200 | F25: BANDEJA TERMICA DM90-A1 (1000ml) | G25: 162x220x52mm | H25: 28097
B26: 0034CON00014 | C26: D742001RLTFY | D26: paq | E26: 200 | F26: TAPA PARA BAND. TERMICA DM90 para (900 y 1000ml) | G26: 173x225x12mm | H26: 24555
B27: 0034CON00015 | C27: D744101RFY | D27: paq | E27: 200 | F27: BANDEJA TERMICA con 3 DIVIS DM100 (1200ml) | G27: 205x260x40mm | H27: 42304
B28: 0034CON00016 | C28: D744101RLTFY | D28: paq | E28: 200 | F28: TAPA PARA BAND TERMICA DM 100 (para 1200ml) | G28: 216x275x12mm | H28: 40979
B29: LOS PRECIOS SON MAS IVA

Sheet Band. Expandido
B3: LISTA DE PRECIOS de 26 DE OCTUBRE 2026 (B18)
C4: COMPAÑÍA LA PILARICA S. A. - DARNEL WWW.DARNELGROUP.COM
B5: CODIGO PILARICA | C5: CODIGO DARNEL | D5: U/M | E5: C/U | F5: DESCRIPCION | G5: COMENTARIO | H5: PRECIO BULTO $
B6: BANDEJAS DE EXPANDIDO ECONOMICAS
B7: 0032ECO00615 | C7: D2001001LE | D7: Bolson | E7: 400 | F7: BANDEJA 615 ECO BLANCA | H7: 23381
B8: 0032ECO00617 | C8: D2001101L | D8: Bolson | E8: 400 | F8: BANDEJA 617 ECO BLANCA | H8: 13789
B9: 0032ECO00618 | C9: D2000201LEE | D9: Bolson | E9: 400 | F9: BANDEJA 618 ECO BLANCA | H9: 17700
B10: 0032ECO00619 | C10: D2000401LEE | D10: Bolson | E10: 400 | F10: BANDEJA 619 ECO BLANCA | H10: 24844
B11: 0032ECO00625 | C11: D2000801LE | D11: Bolson | E11: 200 | F11: BANDEJA 625 ECO BLANCA | H11: 17503
B12: 0032ECO00628 | C12: D20028R01LE | D12: Bolson | E12: 200 | F12: BANDEJA 628 ECO BLANCA PIZZERA | H12: 28905
B13: BANDEJAS DE EXPANDIDO STANDARD
B14: 0032STD00615 | C14: D2001001LE | D14: Bolson | E14: 400 | F14: BANDEJA 615 BLANCA Standard | H14: 28861
B15: 0032STD00617 | C15: D2001101LA | D15: Bolson | E15: 400 | F15: BANDEJA 617 BLANCA Standard | H15: 18115
B16: 0032STD00618 | C16: D2000201LE | D16: Bolson | E16: 400 | F16: BANDEJA 618 BLANCA Standard | H16: 22010
B17: 0032STD00619 | C17: D2000401LE | D17: Bolson | E17: 400 | F17: BANDEJA 619 BLANCA Standard | H17: 30722
B18: 0032STD00625 | C18: D2000801L | D18: Bolson | E18: 200 | F18: BANDEJA 625 BLANCA Standard | H18: 21488
B19: 0032STD00628 | C19: D20028R01L | D19: Bolson | E19: 200 | F19: BANDEJA 628 BLANCA PIZZERA Standard | H19: 37446
B20: OBLEAS DE EXPANDIDO STANDARD
B21: 0032STDO0618 | C21: D00211401L | D21: Bolson | E21: 400 | F21: OBLEA 618 BLANCA Standard | H21: 21712
B22: 0032STDO0619 | C22: D00231801L | D22: Bolson | E22: 400 | F22: OBLEA 619 BLANCA Standard | H22: 27440
B23: BANDEJAS DE EXPANDIDO AUTOABSORBENTES BLANCAS
B24: 0031LIE00615 | C24: D2001001LBB | D24: Bolson | E24: 400 | F24: BAND N° 10BB Bca (10SLE BCA) Absorbentes | H24: =_xlfn.XLOOKUP(B24,lista!A:A,lista!C:C,0,0) -> 52040
B25: 0031LIE00618 | C25: D2000201LBB | D25: Bolson | E25: 400 | F25: BAND N° 2BB Bca (2SLE BCA) Absorbentes | H25: =_xlfn.XLOOKUP(B25,lista!A:A,lista!C:C,0,0) -> 39300
B26: 0031LIE00619 | C26: D2000401LBB | D26: Bolson | E26: 400 | F26: BAND N° 4BB Bca (4SLE BCA) Absorbentes | H26: =_xlfn.XLOOKUP(B26,lista!A:A,lista!C:C,0,0) -> 52858
B27: 0031LIN00625 | C27: D2000801LBBC | D27: Bolson | E27: 200 | F27: BAND N° 8BBC Bca (8SL BCA) Absorbentes | H27: =_xlfn.XLOOKUP(B27,lista!A:A,lista!C:C,0,0) -> 47057
B28: BANDEJAS DE EXPANDIDO STANDARD COLOR
B29: 0032STD02615 | D29: Bolson | E29: 400 | F29: BANDEJA 615 COLOR (AMA, ROSA, NEGRA) Std. | H29: 30175
B30: 0032STD02618 | D30: Bolson | E30: 400 | F30: BANDEJA 618 COLOR (AMA, ROSA, NEGRA) Std. | H30: 23685
B31: 0032STD02619 | D31: Bolson | E31: 400 | F31: BANDEJA 619 COLOR (AMA, ROSA, NEGRA) Std. | H31: 32980
B32: BANDEJAS DE EXPANDIDO REGULARES BIODEGRADABLES
B33: 0032BIO00615 | C33: D2001003LE | D33: Bolson | E33: 400 | F33: BAND N° 10 STD Blanca BIO (615 BIO) | H33: =_xlfn.XLOOKUP(B33,lista!A:A,lista!C:C,0,0) -> 33143
B34: 0032BIO00617 | C34: D2001103LA | D34: Bolson | E34: 400 | F34: BAND N° 11 STD Blanca BIO (617 BIO) | H34: =_xlfn.XLOOKUP(B34,lista!A:A,lista!C:C,0,0) -> 20454
B35: 0032BIO00618 | C35: D2000203LE | D35: Bolson | E35: 400 | F35: BAND. N° 2 STD Blanca BIO (618 BIO) | H35: =_xlfn.XLOOKUP(B35,lista!A:A,lista!C:C,0,0) -> 25667
B36: 0032BIO00619 | C36: D2000403LE | D36: Bolson | E36: 400 | F36: BAND. N° 4 STD Blanca BIO (619 BIO) | H36: =_xlfn.XLOOKUP(B36,lista!A:A,lista!C:C,0,0) -> 35844
B37: 0032BIO00628 | C37: D20028R03L | D37: Bolson | E37: 200 | F37: BAND. N° 28 STD Blanca BIO (628 BIO) | H37: =_xlfn.XLOOKUP(B37,lista!A:A,lista!C:C,0,0) -> 0
B38: BANDEJAS DE EXPANDIDO AUTOABSORBENTES BIODEGRADABLES
C39: D2000203LBB | D39: Bolson | F39: BAND 2SL Absorb. BIO (618 Abs.) | G39: NUEVO | H39: =_xlfn.XLOOKUP(B39,lista!A:A,lista!C:C,0,0) -> 0
C40: D2000403LBB | D40: Bolson | F40: BAND 4SL Absorb. BIO (619 Abs.) | G40: NUEVO | H40: =_xlfn.XLOOKUP(B40,lista!A:A,lista!C:C,0,0) -> 0
C41: D2001003LBB | D41: Bolson | F41: BAND 10SL Absorb. BIO (615 Abs.) | G41: NUEVO | H41: =_xlfn.XLOOKUP(B41,lista!A:A,lista!C:C,0,0) -> 0
C42: D2100803LBBA | D42: Bolson | F42: BAND 8SL Absorb. BIO (625 Abs.) | G42: NUEVO | H42: =_xlfn.XLOOKUP(B42,lista!A:A,lista!C:C,0,0) -> 0
...

Sheet Linea Aluminio
B2: LISTA DE PRECIOS de 26 DE OCTUBRE 2026 (B18)
